<sdf version='1.4'>
  <world name='default'>
    <scene>
      <ambient>0.5 0.5 0.5 1</ambient>
      <background>0.5 0.5 0.5 1</background>
      <shadows>0</shadows>
    </scene>
    <physics type='ode'>
      <gravity>0 0 -9.8</gravity>
      <ode>
        <solver>
          <type>quick</type>
          <iters>200</iters>
          <sor>1.3</sor>
        </solver>
        <constraints>
          <cfm>0</cfm>
          <erp>0.2</erp>
          <contact_max_correcting_vel>100</contact_max_correcting_vel>
          <contact_surface_layer>0.001</contact_surface_layer>
        </constraints>
      </ode>
      <real_time_update_rate>1000</real_time_update_rate>
      <max_step_size>0.002</max_step_size>
      <real_time_factor>1</real_time_factor>
    </physics>
    <model name='plane1_model'>
      <link name='body'>
        <collision name='geom_1'>
          <geometry>
            <plane>
              <normal>0 0 1</normal>
              <size>1 1</size>
            </plane>
          </geometry>
          <surface>
            <friction>
              <ode>
                <mu>1e+08</mu>
                <mu2>1e+08</mu2>
                <fdir1>0 0 0</fdir1>
                <slip1>0</slip1>
                <slip2>0</slip2>
              </ode>
            </friction>
            <bounce>
              <restitution_coefficient>0</restitution_coefficient>
              <threshold>1e+06</threshold>
            </bounce>
            <contact>
              <ode>
                <soft_cfm>0</soft_cfm>
                <soft_erp>0.2</soft_erp>
                <kp>1e+10</kp>
                <kd>1</kd>
                <max_vel>100</max_vel>
                <min_depth>0.0001</min_depth>
              </ode>
            </contact>
          </surface>
          <max_contacts>10</max_contacts>
        </collision>
        <visual name='visual_1'>
          <geometry>
            <plane>
              <normal>0 0 1</normal>
              <size>1 1</size>
            </plane>
          </geometry>
          <material>
            <script>
              <name>__default__</name>
              <uri>__default__</uri>
            </script>
          </material>
          <cast_shadows>0</cast_shadows>
        </visual>
        <velocity_decay>
          <linear>0</linear>
          <angular>0</angular>
        </velocity_decay>
        <self_collide>0</self_collide>
        <kinematic>0</kinematic>
        <gravity>1</gravity>
      </link>
      <static>1</static>
    </model>
    <model name='ens32_walls_model'>
      <pose>1 -1 0 0 -0 0</pose>
      <link name='body'>
        <collision name='geom_1'>
          <geometry>
            <mesh>
              <uri>model://media/models/shademuch.dae</uri>
            </mesh>
          </geometry>
          <surface>
            <bounce/>
            <friction>
              <ode/>
            </friction>
            <contact>
              <ode/>
            </contact>
          </surface>
          <max_contacts>10</max_contacts>
        </collision>
        <visual name='visual_1'>
          <geometry>
            <mesh>
              <uri>model://media/models/shademuch.dae</uri>
            </mesh>
          </geometry>
          <material>
            <script>
              <name>__default__</name>
              <uri>__default__</uri>
            </script>
          </material>
          <cast_shadows>0</cast_shadows>
        </visual>
        <velocity_decay>
          <linear>0</linear>
          <angular>0</angular>
        </velocity_decay>
        <self_collide>0</self_collide>
        <kinematic>0</kinematic>
        <gravity>1</gravity>
      </link>
      <static>1</static>
    </model>
    <light name='my_light_01' type='directional'>
      <pose>0 0 30 0 -0 0</pose>
      <diffuse>0.9 0.9 0.9 1</diffuse>
      <specular>0.6 0.6 0.6 1</specular>
      <attenuation>
        <range>20</range>
      </attenuation>
      <direction>0 0 -1</direction>
      <cast_shadows>0</cast_shadows>
    </light>
    <light name='my_light_02' type='directional'>
      <pose>0 0 30 0 -0 0</pose>
      <diffuse>0.9 0.9 0.9 1</diffuse>
      <specular>0.6 0.6 0.6 1</specular>
      <attenuation>
        <range>20</range>
      </attenuation>
      <direction>-1 0 0</direction>
      <cast_shadows>0</cast_shadows>
    </light>
    <light name='my_light_03' type='directional'>
      <pose>0 0 30 0 -0 0</pose>
      <diffuse>0.9 0.9 0.9 1</diffuse>
      <specular>0.6 0.6 0.6 1</specular>
      <attenuation>
        <range>20</range>
      </attenuation>
      <direction>0 -1 0</direction>
      <cast_shadows>0</cast_shadows>
    </light>
    <light name='my_light_04' type='directional'>
      <pose>0 0 30 0 -0 0</pose>
      <diffuse>0.9 0.9 0.9 1</diffuse>
      <specular>0.6 0.6 0.6 1</specular>
      <attenuation>
        <range>20</range>
      </attenuation>
      <direction>0 0 1</direction>
      <cast_shadows>0</cast_shadows>
    </light>
    <light name='my_light_05' type='directional'>
      <pose>0 0 30 0 -0 0</pose>
      <diffuse>0.9 0.9 0.9 1</diffuse>
      <specular>0.6 0.6 0.6 1</specular>
      <attenuation>
        <range>20</range>
      </attenuation>
      <direction>1 0 0</direction>
      <cast_shadows>0</cast_shadows>
    </light>
    <light name='my_light_06' type='directional'>
      <pose>0 0 30 0 -0 0</pose>
      <diffuse>0.9 0.9 0.9 1</diffuse>
      <specular>0.6 0.6 0.6 1</specular>
      <attenuation>
        <range>20</range>
      </attenuation>
      <direction>0 1 0</direction>
      <cast_shadows>0</cast_shadows>
    </light>
    <spherical_coordinates>
      <surface_model>EARTH_WGS84</surface_model>
      <latitude_deg>0</latitude_deg>
      <longitude_deg>0</longitude_deg>
      <elevation>0</elevation>
      <heading_deg>0</heading_deg>
    </spherical_coordinates>
    <model name='Dumpster'>
      <link name='link'>
        <collision name='collision'>
          <geometry>
            <mesh>
              <uri>model://dumpster/meshes/dumpster.dae</uri>
            </mesh>
          </geometry>
          <max_contacts>10</max_contacts>
          <surface>
            <bounce/>
            <friction>
              <ode/>
            </friction>
            <contact>
              <ode/>
            </contact>
          </surface>
        </collision>
        <visual name='visual'>
          <geometry>
            <mesh>
              <uri>model://dumpster/meshes/dumpster.dae</uri>
            </mesh>
          </geometry>
          <material>
            <script>
              <uri>model://dumpster/materials/scripts</uri>
              <uri>model://dumpster/materials/textures</uri>
              <name>Dumpster/Diffuse</name>
            </script>
          </material>
        </visual>
        <velocity_decay>
          <linear>0</linear>
          <angular>0</angular>
        </velocity_decay>
        <self_collide>0</self_collide>
        <inertial>
          <inertia>
            <ixx>1</ixx>
            <ixy>0</ixy>
            <ixz>0</ixz>
            <iyy>1</iyy>
            <iyz>0</iyz>
            <izz>1</izz>
          </inertia>
          <mass>1</mass>
        </inertial>
        <kinematic>0</kinematic>
        <gravity>1</gravity>
      </link>
      <pose>0 3 0 0 -0 0</pose>
      <static>0</static>
    </model>
    <model name='mud_box'>
      <static>1</static>
      <link name='link'>
        <collision name='collision'>
          <geometry>
            <box>
              <size>8 10 0.2</size>
            </box>
          </geometry>
          <max_contacts>10</max_contacts>
          <surface>
            <bounce/>
            <friction>
              <ode>
                <mu>1e+08</mu>
                <mu2>1e+08</mu2>
                <fdir1>0 0 0</fdir1>
                <slip1>0</slip1>
                <slip2>0</slip2>
              </ode>
            </friction>
            <contact>
              <ode/>
            </contact>
          </surface>
        </collision>
        <visual name='visual_1'>
          <pose>-2 2.5 0 0 -0 0</pose>
          <cast_shadows>0</cast_shadows>
          <geometry>
            <box>
              <size>4 5 0.2</size>
            </box>
          </geometry>
          <material>
            <script>
              <uri>model://mud_box/materials/scripts</uri>
              <uri>model://mud_box/materials/textures</uri>
              <name>vrc/mud</name>
            </script>
          </material>
        </visual>
        <visual name='visual_2'>
          <pose>2 2.5 0 0 -0 0</pose>
          <cast_shadows>0</cast_shadows>
          <geometry>
            <box>
              <size>4 5 0.2</size>
            </box>
          </geometry>
          <material>
            <script>
              <uri>model://mud_box/materials/scripts</uri>
              <uri>model://mud_box/materials/textures</uri>
              <name>vrc/mud</name>
            </script>
          </material>
        </visual>
        <visual name='visual_3'>
          <pose>2 -2.5 0 0 -0 0</pose>
          <cast_shadows>0</cast_shadows>
          <geometry>
            <box>
              <size>4 5 0.2</size>
            </box>
          </geometry>
          <material>
            <script>
              <uri>model://mud_box/materials/scripts</uri>
              <uri>model://mud_box/materials/textures</uri>
              <name>vrc/mud</name>
            </script>
          </material>
        </visual>
        <visual name='visual_4'>
          <pose>-2 -2.5 0 0 -0 0</pose>
          <cast_shadows>0</cast_shadows>
          <geometry>
            <box>
              <size>4 5 0.2</size>
            </box>
          </geometry>
          <material>
            <script>
              <uri>model://mud_box/materials/scripts</uri>
              <uri>model://mud_box/materials/textures</uri>
              <name>vrc/mud</name>
            </script>
          </material>
        </visual>
        <velocity_decay>
          <linear>0</linear>
          <angular>0</angular>
        </velocity_decay>
        <self_collide>0</self_collide>
        <kinematic>0</kinematic>
        <gravity>1</gravity>
      </link>
      <pose>-3 3 0 0 -0 0</pose>
    </model>
    <model name='coke_can_1'>
      <link name='link'>
        <inertial>
          <pose>-0.01 -0.012 0.15 0 -0 0</pose>
          <mass>0.39</mass>
          <inertia>
            <ixx>0.00058</ixx>
            <ixy>0</ixy>
            <ixz>0</ixz>
            <iyy>0.00058</iyy>
            <iyz>0</iyz>
            <izz>0.00019</izz>
          </inertia>
        </inertial>
        <collision name='collision'>
          <pose>0 0 -0.46 0 -0 0</pose>
          <geometry>
            <mesh>
              <uri>model://coke_can/meshes/coke_can.dae</uri>
            </mesh>
          </geometry>
          <surface>
            <friction>
              <ode>
                <mu>1</mu>
                <mu2>1</mu2>
              </ode>
            </friction>
            <contact>
              <ode>
                <kp>1e+07</kp>
                <kd>1</kd>
                <min_depth>0.001</min_depth>
                <max_vel>0.1</max_vel>
              </ode>
            </contact>
            <bounce/>
          </surface>
          <max_contacts>10</max_contacts>
        </collision>
        <visual name='visual'>
          <pose>0 0 -0.46 0 -0 0</pose>
          <geometry>
            <mesh>
              <uri>model://coke_can/meshes/coke_can.dae</uri>
            </mesh>
          </geometry>
        </visual>
        <velocity_decay>
          <linear>0</linear>
          <angular>0</angular>
        </velocity_decay>
        <self_collide>0</self_collide>
        <kinematic>0</kinematic>
        <gravity>1</gravity>
      </link>
      <pose>-0.527277 1 0 0 -0 0</pose>
      <static>0</static>
    </model>
    <state world_name='default'>
      <sim_time>33655 526000000</sim_time>
      <real_time>374 563920192</real_time>
      <wall_time>1473006890 467072292</wall_time>
      <model name='Dumpster'>
        <pose>0.001347 2.99916 0.100917 0 -2e-06 -9.3e-05</pose>
        <link name='link'>
          <pose>0.001347 2.99916 0.100917 0 -2e-06 -9.3e-05</pose>
          <velocity>0 0 0 0 -0 0</velocity>
          <acceleration>-0.00978 3.8e-05 5.65498 3.10388 1.14254 3.14158</acceleration>
          <wrench>-0.00978 3.8e-05 5.65498 0 -0 0</wrench>
        </link>
      </model>
      <model name='coke_can'>
        <pose>0.311307 0.420581 0.095501 -0.013074 -0.01721 -0.025429</pose>
        <link name='link'>
          <pose>0.311307 0.420581 0.095501 -0.013074 -0.01721 -0.025429</pose>
          <velocity>0 0 0 0 -0 0</velocity>
          <acceleration>0.000773 0.002072 0.000101 -2.1e-05 8e-06 -2.58494e-26</acceleration>
          <wrench>0.000301 0.000808 3.9e-05 0 -0 0</wrench>
        </link>
      </model>
      <model name='coke_can_0'>
        <pose>-0.64015 -0.02717 0.095765 -0.019267 -0.003362 -0.086548</pose>
        <link name='link'>
          <pose>-0.64015 -0.02717 0.095765 -0.019267 -0.003362 -0.086548</pose>
          <velocity>0 0 0 0 -0 0</velocity>
          <acceleration>-6e-06 -1.1e-05 -1e-06 0 -0 0</acceleration>
          <wrench>-2e-06 -4e-06 -0 0 -0 0</wrench>
        </link>
      </model>
      <model name='coke_can_1'>
        <pose>-0.839353 -0.281654 0.095498 -0.013059 -0.017031 0.064075</pose>
        <link name='link'>
          <pose>-0.839353 -0.281654 0.095498 -0.013059 -0.017031 0.064075</pose>
          <velocity>0 0 0 0 -0 0</velocity>
          <acceleration>0 -0 0 0 -0 0</acceleration>
          <wrench>0 -0 0 0 -0 0</wrench>
        </link>
      </model>
      <model name='coke_can_2'>
        <pose>-0.789627 -0.562378 0.09547 -0.012925 -0.015501 -0.075609</pose>
        <link name='link'>
          <pose>-0.789627 -0.562378 0.09547 -0.012925 -0.015501 -0.075609</pose>
          <velocity>0 0 0 0 -0 0</velocity>
          <acceleration>-3e-06 -5e-06 0 0 -0 0</acceleration>
          <wrench>-1e-06 -2e-06 0 0 -0 0</wrench>
        </link>
      </model>
      <model name='coke_can_3'>
        <pose>-1.0468 0.463878 0.095501 -0.013074 -0.01721 0.054865</pose>
        <link name='link'>
          <pose>-1.0468 0.463878 0.095501 -0.013074 -0.01721 0.054865</pose>
          <velocity>0 0 0 0 -0 0</velocity>
          <acceleration>4.3e-05 -0.001213 4.2e-05 1.2e-05 -0 0</acceleration>
          <wrench>1.7e-05 -0.000473 1.6e-05 0 -0 0</wrench>
        </link>
      </model>
      <model name='ens32_walls_model'>
        <pose>0.862026 -1.11107 0 0 -0 0</pose>
        <link name='body'>
          <pose>0.862026 -1.11107 0 0 -0 0</pose>
          <velocity>0 0 0 0 -0 0</velocity>
          <acceleration>0 0 0 0 -0 0</acceleration>
          <wrench>0 0 0 0 -0 0</wrench>
        </link>
      </model>
      <model name='mud_box'>
        <pose>-2.11203 2.92245 0 0 -0 0</pose>
        <link name='link'>
          <pose>-2.11203 2.92245 0 0 -0 0</pose>
          <velocity>0 0 0 0 -0 0</velocity>
          <acceleration>0 0 0 0 -0 0</acceleration>
          <wrench>0 0 0 0 -0 0</wrench>
        </link>
      </model>
      <model name='plane1_model'>
        <pose>0 0 0 0 -0 0</pose>
        <link name='body'>
          <pose>0 0 0 0 -0 0</pose>
          <velocity>0 0 0 0 -0 0</velocity>
          <acceleration>0 0 0 0 -0 0</acceleration>
          <wrench>0 0 0 0 -0 0</wrench>
        </link>
      </model>
      <model name='vizzy'>
        <pose>-1.5 -0 0.1 0 -0 0</pose>
        <link name='base_link'>
          <pose>-1.5 -0 0.1 0 -0 0</pose>
          <velocity>-0 -0 -0 0 -0 0</velocity>
          <acceleration>-0 -0 -6e-05 0 -0 0.000363</acceleration>
          <wrench>-0 -0 -0.00012 0 -0 0</wrench>
        </link>
        <link name='eyes_tilt_link'>
          <pose>-1.41148 0.098321 0.475155 -1.57027 -0.041745 0.839368</pose>
          <velocity>-0 -0 -0 0 -0 0</velocity>
          <acceleration>-1.2e-05 -8e-06 -5.5e-05 0 -0 0</acceleration>
          <wrench>-5e-06 -3e-06 -2.3e-05 0 -0 0</wrench>
        </link>
        <link name='l_eye_link'>
          <pose>-1.48739 0.166448 0.475208 -3.06094 -0.318128 -2.5566</pose>
          <velocity>-0 -0 -0 0 -0 2e-06</velocity>
          <acceleration>-7e-06 -4e-06 -5.3e-05 0 -0 0</acceleration>
          <wrench>-1e-06 -1e-06 -8e-06 0 -0 0</wrench>
        </link>
        <link name='neck_pan_link'>
          <pose>-1.49998 -0 0.1 3.14108 0.000606 -2.30217</pose>
          <velocity>-0 -0 -0 0 -0 0</velocity>
          <acceleration>-1.8e-05 -0 -6e-05 0 -0 -1e-06</acceleration>
          <wrench>-4e-06 -0 -1.3e-05 0 -0 0</wrench>
        </link>
        <link name='neck_tilt_link'>
          <pose>-1.49998 -0.000295 0.47 -1.57135 -0.327859 -2.30202</pose>
          <velocity>-0 -0 -0 0 -0 0</velocity>
          <acceleration>-1.6e-05 -3e-06 -5.8e-05 0 -0 0</acceleration>
          <wrench>-5e-06 -1e-06 -1.7e-05 0 -0 0</wrench>
        </link>
        <link name='r_eye_link'>
          <pose>-1.33557 0.030194 0.475102 3.05988 -0.317865 -2.04747</pose>
          <velocity>-0 -0 -0 -0 -0 -2e-06</velocity>
          <acceleration>-1.5e-05 -1.3e-05 -5.5e-05 0 -0 0</acceleration>
          <wrench>-2e-06 -2e-06 -9e-06 0 -0 0</wrench>
        </link>
      </model>
    </state>
    <gui fullscreen='0'>
      <camera name='user_camera'>
        <pose>-1.0304 0.107316 4.26901 0 1.54818 -0.008584</pose>
        <view_controller>orbit</view_controller>
      </camera>
    </gui>
    <model name='coke_can_3'>
      <link name='link'>
        <inertial>
          <pose>-0.01 -0.012 0.15 0 -0 0</pose>
          <mass>0.39</mass>
          <inertia>
            <ixx>0.00058</ixx>
            <ixy>0</ixy>
            <ixz>0</ixz>
            <iyy>0.00058</iyy>
            <iyz>0</iyz>
            <izz>0.00019</izz>
          </inertia>
        </inertial>
        <collision name='collision'>
          <pose>0 0 -0.46 0 -0 0</pose>
          <geometry>
            <mesh>
              <uri>model://coke_can/meshes/coke_can.dae</uri>
            </mesh>
          </geometry>
          <surface>
            <friction>
              <ode>
                <mu>1</mu>
                <mu2>1</mu2>
              </ode>
            </friction>
            <contact>
              <ode>
                <kp>1e+07</kp>
                <kd>1</kd>
                <min_depth>0.001</min_depth>
                <max_vel>0.1</max_vel>
              </ode>
            </contact>
            <bounce/>
          </surface>
          <max_contacts>10</max_contacts>
        </collision>
        <visual name='visual'>
          <pose>0 0 -0.46 0 -0 0</pose>
          <geometry>
            <mesh>
              <uri>model://coke_can/meshes/coke_can.dae</uri>
            </mesh>
          </geometry>
        </visual>
        <velocity_decay>
          <linear>0</linear>
          <angular>0</angular>
        </velocity_decay>
        <self_collide>0</self_collide>
        <kinematic>0</kinematic>
        <gravity>1</gravity>
      </link>
      <pose>-1 0 0 0 -0 0</pose>
      <static>0</static>
    </model>
    <model name='coke_can'>
      <link name='link'>
        <inertial>
          <pose>-0.01 -0.012 0.15 0 -0 0</pose>
          <mass>0.39</mass>
          <inertia>
            <ixx>0.00058</ixx>
            <ixy>0</ixy>
            <ixz>0</ixz>
            <iyy>0.00058</iyy>
            <iyz>0</iyz>
            <izz>0.00019</izz>
          </inertia>
        </inertial>
        <collision name='collision'>
          <pose>0 0 -0.46 0 -0 0</pose>
          <geometry>
            <mesh>
              <uri>model://coke_can/meshes/coke_can.dae</uri>
            </mesh>
          </geometry>
          <surface>
            <friction>
              <ode>
                <mu>1</mu>
                <mu2>1</mu2>
              </ode>
            </friction>
            <contact>
              <ode>
                <kp>1e+07</kp>
                <kd>1</kd>
                <min_depth>0.001</min_depth>
                <max_vel>0.1</max_vel>
              </ode>
            </contact>
            <bounce/>
          </surface>
          <max_contacts>10</max_contacts>
        </collision>
        <visual name='visual'>
          <pose>0 0 -0.46 0 -0 0</pose>
          <geometry>
            <mesh>
              <uri>model://coke_can/meshes/coke_can.dae</uri>
            </mesh>
          </geometry>
        </visual>
        <velocity_decay>
          <linear>0</linear>
          <angular>0</angular>
        </velocity_decay>
        <self_collide>0</self_collide>
        <kinematic>0</kinematic>
        <gravity>1</gravity>
      </link>
      <pose>0.456222 1 0 0 -0 0</pose>
      <static>0</static>
    </model>
    <model name='coke_can_0'>
      <link name='link'>
        <inertial>
          <pose>-0.01 -0.012 0.15 0 -0 0</pose>
          <mass>0.39</mass>
          <inertia>
            <ixx>0.00058</ixx>
            <ixy>0</ixy>
            <ixz>0</ixz>
            <iyy>0.00058</iyy>
            <iyz>0</iyz>
            <izz>0.00019</izz>
          </inertia>
        </inertial>
        <collision name='collision'>
          <pose>0 0 -0.46 0 -0 0</pose>
          <geometry>
            <mesh>
              <uri>model://coke_can/meshes/coke_can.dae</uri>
            </mesh>
          </geometry>
          <surface>
            <friction>
              <ode>
                <mu>1</mu>
                <mu2>1</mu2>
              </ode>
            </friction>
            <contact>
              <ode>
                <kp>1e+07</kp>
                <kd>1</kd>
                <min_depth>0.001</min_depth>
                <max_vel>0.1</max_vel>
              </ode>
            </contact>
            <bounce/>
          </surface>
          <max_contacts>10</max_contacts>
        </collision>
        <visual name='visual'>
          <pose>0 0 -0.46 0 -0 0</pose>
          <geometry>
            <mesh>
              <uri>model://coke_can/meshes/coke_can.dae</uri>
            </mesh>
          </geometry>
        </visual>
        <velocity_decay>
          <linear>0</linear>
          <angular>0</angular>
        </velocity_decay>
        <self_collide>0</self_collide>
        <kinematic>0</kinematic>
        <gravity>1</gravity>
      </link>
      <pose>0.458032 -0.467959 0 0 -0 0</pose>
      <static>0</static>
    </model>
    <model name='coke_can_2'>
      <link name='link'>
        <inertial>
          <pose>-0.01 -0.012 0.15 0 -0 0</pose>
          <mass>0.39</mass>
          <inertia>
            <ixx>0.00058</ixx>
            <ixy>0</ixy>
            <ixz>0</ixz>
            <iyy>0.00058</iyy>
            <iyz>0</iyz>
            <izz>0.00019</izz>
          </inertia>
        </inertial>
        <collision name='collision'>
          <pose>0 0 -0.46 0 -0 0</pose>
          <geometry>
            <mesh>
              <uri>model://coke_can/meshes/coke_can.dae</uri>
            </mesh>
          </geometry>
          <surface>
            <friction>
              <ode>
                <mu>1</mu>
                <mu2>1</mu2>
              </ode>
            </friction>
            <contact>
              <ode>
                <kp>1e+07</kp>
                <kd>1</kd>
                <min_depth>0.001</min_depth>
                <max_vel>0.1</max_vel>
              </ode>
            </contact>
            <bounce/>
          </surface>
          <max_contacts>10</max_contacts>
        </collision>
        <visual name='visual'>
          <pose>0 0 -0.46 0 -0 0</pose>
          <geometry>
            <mesh>
              <uri>model://coke_can/meshes/coke_can.dae</uri>
            </mesh>
          </geometry>
        </visual>
        <velocity_decay>
          <linear>0</linear>
          <angular>0</angular>
        </velocity_decay>
        <self_collide>0</self_collide>
        <kinematic>0</kinematic>
        <gravity>1</gravity>
      </link>
      <pose>0 -0.436271 0 0 -0 0</pose>
      <static>0</static>
    </model>
    <model name='vizzy'>
      <link name='base_link'>
        <pose>0 0 0 0 -0 0</pose>
        <inertial>
          <pose>-2.34513e-10 -1.47247e-07 0.0626537 0 -0 0</pose>
          <mass>2.001</mass>
          <inertia>
            <ixx>200.009</ixx>
            <ixy>-1.38181e-13</ixy>
            <ixz>1.44225e-10</ixz>
            <iyy>200.009</iyy>
            <iyz>9.05566e-08</iyz>
            <izz>200.001</izz>
          </inertia>
        </inertial>
        <collision name='base_link_collision'>
          <pose>0 0 0.125 0 -0 0</pose>
          <geometry>
            <cylinder>
              <length>0.25</length>
              <radius>0.01</radius>
            </cylinder>
          </geometry>
          <surface>
            <contact>
              <ode/>
            </contact>
            <friction>
              <ode>
                <mu>0.2</mu>
                <mu2>0.2</mu2>
              </ode>
            </friction>
            <bounce/>
          </surface>
          <max_contacts>10</max_contacts>
        </collision>
        <visual name='base_link_visual'>
          <pose>0 0 0.125 0 -0 0</pose>
          <geometry>
            <cylinder>
              <length>0.25</length>
              <radius>0.01</radius>
            </cylinder>
          </geometry>
        </visual>
        <velocity_decay>
          <linear>0</linear>
          <angular>0</angular>
        </velocity_decay>
        <gravity>1</gravity>
        <velocity_decay>
          <linear>0</linear>
          <angular>0</angular>
        </velocity_decay>
        <self_collide>0</self_collide>
        <kinematic>0</kinematic>
      </link>
      <joint name='fixed' type='revolute'>
        <child>base_link</child>
        <parent>world</parent>
        <axis>
          <limit>
            <lower>0</lower>
            <upper>0</upper>
          </limit>
          <dynamics>
            <damping>0</damping>
          </dynamics>
          <xyz>0 0 1</xyz>
        </axis>
      </joint>
      <link name='neck_pan_link'>
        <pose>0 0 0 3.1408 5.93982e-20 3.14</pose>
        <inertial>
          <pose>0 0 -0.327 0 0 -1.5708</pose>
          <mass>0.223144</mass>
          <inertia>
            <ixx>0.000359045</ixx>
            <ixy>3.18554e-08</ixy>
            <ixz>-1.3374e-05</ixz>
            <iyy>0.000368715</iyy>
            <iyz>-4.52682e-07</iyz>
            <izz>8.59049e-05</izz>
          </inertia>
        </inertial>
        <collision name='neck_pan_link_collision'>
          <pose>0 0 -0.327 0 0 -1.5708</pose>
          <geometry>
            <mesh>
              <scale>1 1 1</scale>
              <uri>/home/rui/catkin_ws/src/vizzy/vizzy_description/meshes/M1.dae</uri>
            </mesh>
          </geometry>
          <max_contacts>10</max_contacts>
          <surface>
            <bounce/>
            <friction>
              <ode/>
            </friction>
            <contact>
              <ode/>
            </contact>
          </surface>
        </collision>
        <visual name='neck_pan_link_visual'>
          <pose>0 0 -0.327 0 0 -1.5708</pose>
          <geometry>
            <mesh>
              <scale>1 1 1</scale>
              <uri>/home/rui/catkin_ws/src/vizzy/vizzy_description/meshes/M1.dae</uri>
            </mesh>
          </geometry>
        </visual>
        <gravity>1</gravity>
        <velocity_decay>
          <linear>0</linear>
          <angular>0</angular>
        </velocity_decay>
        <self_collide>0</self_collide>
        <kinematic>0</kinematic>
      </link>
      <joint name='neck_pan_joint' type='revolute'>
        <child>neck_pan_link</child>
        <parent>base_link</parent>
        <axis>
          <xyz>1e-06 0.000796 -1</xyz>
          <limit>
            <lower>-2.02502</lower>
            <upper>2.02502</upper>
            <effort>100</effort>
            <velocity>5</velocity>
          </limit>
          <dynamics>
            <damping>5</damping>
          </dynamics>
        </axis>
      </joint>
      <link name='neck_tilt_link'>
        <pose>-4.69261e-07 -0.000294641 0.37 -1.57159 3.25261e-19 3.14</pose>
        <inertial>
          <pose>-0.0269098 -0.0270686 0 2.06823e-13 -2.06823e-13 3.14159</pose>
          <mass>0.299441</mass>
          <inertia>
            <ixx>0.00129465</ixx>
            <ixy>0.000129114</ixy>
            <ixz>-4.90947e-05</ixz>
            <iyy>0.00182136</iyy>
            <iyz>-2.69741e-05</iyz>
            <izz>0.00185546</izz>
          </inertia>
        </inertial>
        <collision name='neck_tilt_link_collision'>
          <pose>-0.027 -0.027 0 2.06823e-13 -2.06823e-13 3.14159</pose>
          <geometry>
            <mesh>
              <scale>1 1 1</scale>
              <uri>/home/rui/catkin_ws/src/vizzy/vizzy_description/meshes/M2.dae</uri>
            </mesh>
          </geometry>
          <max_contacts>10</max_contacts>
          <surface>
            <bounce/>
            <friction>
              <ode/>
            </friction>
            <contact>
              <ode/>
            </contact>
          </surface>
        </collision>
        <visual name='neck_tilt_link_visual'>
          <pose>-0.027 -0.027 0 2.06823e-13 -2.06823e-13 3.14159</pose>
          <geometry>
            <mesh>
              <scale>1 1 1</scale>
              <uri>/home/rui/catkin_ws/src/vizzy/vizzy_description/meshes/M2.dae</uri>
            </mesh>
          </geometry>
        </visual>
        <gravity>1</gravity>
        <velocity_decay>
          <linear>0</linear>
          <angular>0</angular>
        </velocity_decay>
        <self_collide>0</self_collide>
        <kinematic>0</kinematic>
      </link>
      <joint name='neck_tilt_joint' type='revolute'>
        <child>neck_tilt_link</child>
        <parent>neck_pan_link</parent>
        <axis>
          <xyz>-0.001593 -0.999998 -0.000796</xyz>
          <limit>
            <lower>-2.01416</lower>
            <upper>2.45772</upper>
            <effort>100</effort>
            <velocity>5</velocity>
          </limit>
          <dynamics>
            <damping>0</damping>
          </dynamics>
        </axis>
      </joint>
      <link name='eyes_tilt_link'>
        <pose>0.123789 -0.00052966 0.41755 -1.56994 -0.369599 -0.00190115</pose>
        <inertial>
          <pose>-0.00373829 -0.00106808 -0.00106808 0 0 -1.2012</pose>
          <mass>0.429223</mass>
          <inertia>
            <ixx>0.00336253</ixx>
            <ixy>-1.51155e-06</ixy>
            <ixz>-6.24898e-07</ixz>
            <iyy>0.00328657</iyy>
            <iyz>-3.71754e-06</iyz>
            <izz>0.00213784</izz>
          </inertia>
        </inertial>
        <collision name='eyes_tilt_link_collision'>
          <pose>-0.007 -0.002 -0.002 0 0 -1.2012</pose>
          <geometry>
            <mesh>
              <scale>1 1 1</scale>
              <uri>/home/rui/catkin_ws/src/vizzy/vizzy_description/meshes/M3.dae</uri>
            </mesh>
          </geometry>
          <max_contacts>10</max_contacts>
          <surface>
            <bounce/>
            <friction>
              <ode/>
            </friction>
            <contact>
              <ode/>
            </contact>
          </surface>
        </collision>
        <visual name='eyes_tilt_link_visual'>
          <pose>-0.007 -0.002 -0.002 0 0 -1.2012</pose>
          <geometry>
            <mesh>
              <scale>1 1 1</scale>
              <uri>/home/rui/catkin_ws/src/vizzy/vizzy_description/meshes/M3.dae</uri>
            </mesh>
          </geometry>
        </visual>
        <gravity>1</gravity>
        <velocity_decay>
          <linear>0</linear>
          <angular>0</angular>
        </velocity_decay>
        <self_collide>0</self_collide>
        <kinematic>0</kinematic>
      </link>
      <joint name='eyes_tilt_joint' type='revolute'>
        <child>eyes_tilt_link</child>
        <parent>neck_tilt_link</parent>
        <axis>
          <xyz>0.001593 0.999998 0.000796</xyz>
          <limit>
            <lower>-0.663225</lower>
            <upper>0.663225</upper>
            <effort>10</effort>
            <velocity>5</velocity>
          </limit>
          <dynamics>
            <damping>0</damping>
          </dynamics>
        </axis>
      </joint>
      <link name='l_eye_link'>
        <pose>0.123952 0.10147 0.417631 3.1408 -2.09674e-13 3.14</pose>
        <inertial>
          <pose>0 0 0 0 -0 1.5708</pose>
          <mass>0.158521</mass>
          <inertia>
            <ixx>0.000147615</ixx>
            <ixy>-1.56211e-09</ixy>
            <ixz>8.85545e-10</ixz>
            <iyy>0.00017784</iyy>
            <iyz>8.21234e-06</iyz>
            <izz>0.000144885</izz>
          </inertia>
        </inertial>
        <collision name='l_eye_link_collision'>
          <pose>0 0 0 0 -0 1.5708</pose>
          <geometry>
            <mesh>
              <scale>1 1 1</scale>
              <uri>/home/rui/catkin_ws/src/vizzy/vizzy_description/meshes/M4.dae</uri>
            </mesh>
          </geometry>
          <max_contacts>10</max_contacts>
          <surface>
            <bounce/>
            <friction>
              <ode/>
            </friction>
            <contact>
              <ode/>
            </contact>
          </surface>
        </collision>
        <visual name='l_eye_link_visual'>
          <pose>0 0 0 0 -0 1.5708</pose>
          <geometry>
            <mesh>
              <scale>1 1 1</scale>
              <uri>/home/rui/catkin_ws/src/vizzy/vizzy_description/meshes/M4.dae</uri>
            </mesh>
          </geometry>
        </visual>
        <visual name='l_eye_link_visual_l_camera_link'>
          <pose>-0.0275 0 0 -3.14159 -2.06823e-13 3.14159</pose>
          <geometry>
            <box>
              <size>0.001 0.001 0.001</size>
            </box>
          </geometry>
        </visual>
        <visual name='l_eye_link_visual_l_camera_vision_link'>
          <pose>0 0 0 1.5708 5.55112e-17 -1.5708</pose>
          <geometry>
            <box>
              <size>0.001 0.001 0.001</size>
            </box>
          </geometry>
        </visual>
        <gravity>1</gravity>
        <velocity_decay>
          <linear>0</linear>
          <angular>0</angular>
        </velocity_decay>
        <self_collide>0</self_collide>
        <sensor name='l_camera' type='camera'>
          <update_rate>30</update_rate>
          <camera name='head'>
            <horizontal_fov>1.5708</horizontal_fov>
            <image>
              <width>320</width>
              <height>240</height>
              <format>R8G8B8</format>
            </image>
            <clip>
              <near>0.02</near>
              <far>300</far>
            </clip>
            <noise>
              <type>gaussian</type>
              <mean>0</mean>
              <stddev>0</stddev>
            </noise>
          </camera>
          <plugin name='camera_controller' filename='libgazebo_ros_camera.so'>
            <alwaysOn>true</alwaysOn>
            <updateRate>30.0</updateRate>
            <cameraName>vizzy/l_camera</cameraName>
            <imageTopicName>image_raw</imageTopicName>
            <cameraInfoTopicName>camera_info</cameraInfoTopicName>
            <frameName>l_camera_link</frameName>
            <robotNamespace>/</robotNamespace>
          </plugin>
          <pose>-0.0275 0 0 -3.14159 -2.06823e-13 3.14159</pose>
        </sensor>
        <kinematic>0</kinematic>
      </link>
      <joint name='l_eye_joint' type='revolute'>
        <child>l_eye_link</child>
        <parent>eyes_tilt_link</parent>
        <axis>
          <xyz>1e-06 0.000796 -1</xyz>
          <limit>
            <lower>-1</lower>
            <upper>1</upper>
            <effort>1000</effort>
            <velocity>5</velocity>
          </limit>
          <dynamics>
            <damping>0</damping>
          </dynamics>
        </axis>
      </joint>
      <link name='r_eye_link'>
        <pose>0.123627 -0.102529 0.417469 3.1408 -2.09674e-13 3.14</pose>
        <inertial>
          <pose>0 0 0 0 -0 1.5708</pose>
          <mass>0.158521</mass>
          <inertia>
            <ixx>0.000147615</ixx>
            <ixy>-1.56211e-09</ixy>
            <ixz>8.85545e-10</ixz>
            <iyy>0.00017784</iyy>
            <iyz>8.21234e-06</iyz>
            <izz>0.000144885</izz>
          </inertia>
        </inertial>
        <collision name='r_eye_link_collision'>
          <pose>0 0 0 0 -0 1.5708</pose>
          <geometry>
            <mesh>
              <scale>1 1 1</scale>
              <uri>/home/rui/catkin_ws/src/vizzy/vizzy_description/meshes/M4.dae</uri>
            </mesh>
          </geometry>
          <max_contacts>10</max_contacts>
          <surface>
            <bounce/>
            <friction>
              <ode/>
            </friction>
            <contact>
              <ode/>
            </contact>
          </surface>
        </collision>
        <visual name='r_eye_link_visual'>
          <pose>0 0 0 0 -0 1.5708</pose>
          <geometry>
            <mesh>
              <scale>1 1 1</scale>
              <uri>/home/rui/catkin_ws/src/vizzy/vizzy_description/meshes/M4.dae</uri>
            </mesh>
          </geometry>
        </visual>
        <visual name='r_eye_link_visual_r_camera_link'>
          <pose>-0.0275 0 0 -3.14159 -2.06823e-13 3.14159</pose>
          <geometry>
            <box>
              <size>0.001 0.001 0.001</size>
            </box>
          </geometry>
        </visual>
        <visual name='r_eye_link_visual_r_camera_vision_link'>
          <pose>0 0 0 1.5708 5.55112e-17 -1.5708</pose>
          <geometry>
            <box>
              <size>0.001 0.001 0.001</size>
            </box>
          </geometry>
        </visual>
        <gravity>1</gravity>
        <velocity_decay>
          <linear>0</linear>
          <angular>0</angular>
        </velocity_decay>
        <self_collide>0</self_collide>
        <sensor name='r_camera' type='camera'>
          <update_rate>30</update_rate>
          <camera name='head'>
            <horizontal_fov>1.5708</horizontal_fov>
            <image>
              <width>320</width>
              <height>240</height>
              <format>R8G8B8</format>
            </image>
            <clip>
              <near>0.02</near>
              <far>300</far>
            </clip>
            <noise>
              <type>gaussian</type>
              <mean>0</mean>
              <stddev>0</stddev>
            </noise>
          </camera>
          <plugin name='camera_controller' filename='libgazebo_ros_camera.so'>
            <alwaysOn>true</alwaysOn>
            <updateRate>30.0</updateRate>
            <cameraName>vizzy/r_camera</cameraName>
            <imageTopicName>image_raw</imageTopicName>
            <cameraInfoTopicName>camera_info</cameraInfoTopicName>
            <frameName>r_camera_link</frameName>
            <robotNamespace>/</robotNamespace>
          </plugin>
          <pose>-0.0275 0 0 -3.14159 -2.06823e-13 3.14159</pose>
        </sensor>
        <kinematic>0</kinematic>
      </link>
      <joint name='r_eye_joint' type='revolute'>
        <child>r_eye_link</child>
        <parent>eyes_tilt_link</parent>
        <axis>
          <xyz>1e-06 0.000796 -1</xyz>
          <limit>
            <lower>-1</lower>
            <upper>1</upper>
            <effort>1000</effort>
            <velocity>5</velocity>
          </limit>
          <dynamics>
            <damping>0</damping>
          </dynamics>
        </axis>
      </joint>
      <static>0</static>
      <plugin name='gazebo_ros_control' filename='libgazebo_ros_control.so'>
        <robotNamespace>/vizzy</robotNamespace>
      </plugin>
      <pose>-1.5 0 0.1 0 -0 0</pose>
    </model>
  </world>
</sdf>
