<?xml version="1.0"?>
<robot xmlns:sensor="http://playerstage.sourceforge.net/gazebo/xmlschema/#sensor"
       xmlns:controller="http://playerstage.sourceforge.net/gazebo/xmlschema/#controller"
       xmlns:interface="http://playerstage.sourceforge.net/gazebo/xmlschema/#interface"
       xmlns:xacro="http://ros.org/wiki/xacro">

  <!-- Things that are needed only for Gazebo (not the physical robot).  These include
       sensor and controller plugin specifications -->
  <xacro:include filename="$(find vizzy_description)/urdf/head/head.gazebo.xacro"/>
  <xacro:include filename="$(find vizzy_description)/urdf/head/head.transmission.xacro"/>

  <xacro:macro name="head" params="name parent">

    <link name="neck_pan_link">
      <xacro:vizzy_neck_pan_link_inertial/>
      <visual>
        <origin
          xyz="0 0 -0.327"
          rpy="0 0 ${-M_PI/2}"/>
        <geometry>
          <mesh
            filename="package://vizzy_description/meshes/head/neck_pan.dae"/>
        </geometry>
        <material name="light_gray_3"/>
      </visual>
      <xacro:vizzy_neck_pan_link_collision/>
    </link>

    <joint name="neck_pan_joint"
      type="revolute">
      <origin
        xyz="0 0 0"
        rpy="${M_PI/2} 0 0"/>
      <parent
        link="${parent}"/>
      <child
        link="neck_pan_link"/>
      <axis
        xyz="0 0 1"/>
      <!--
        <limit lower="-0.925024504" upper="0.925024504" effort="10.0" velocity="5.0" />
      -->
      <dynamics damping="5.0" friction="10.0"/>
      <limit lower="-2.025024504" upper="2.025024504" effort="100.0" velocity="5.0"/>
    </joint>

    <!-- Neck tilt -->
    <link name="neck_tilt_link">
      <xacro:vizzy_neck_tilt_link_inertial/>
      <visual>
        <origin
          xyz="-0.027 -0.027 0"
          rpy="${M_PI} ${M_PI} 0"/>
        <geometry>
          <mesh
            filename="package://vizzy_description/meshes/head/neck_tilt.dae"/>
        </geometry>
        <material name="light_gray_1"/>
      </visual>
      <xacro:vizzy_neck_tilt_link_collision/>
    </link>

    <joint name="neck_tilt_joint"
      type="revolute">
      <origin
        xyz="0 0 -0.370"
        rpy="${M_PI/2} 0 0"/>
      <parent
        link="neck_pan_link"/>
      <child
        link="neck_tilt_link"/>
      <axis
        xyz="0 0 1"/>
      <!--<limit lower="-0.314159265" upper="0.645771823" effort="100.0" velocity="5.0" />-->
      <dynamics damping="0.0" friction="5.0"/>
      <limit lower="-2.014159265" upper="2.45771823" effort="100.0" velocity="5.0"/>
    </joint>

    <!-- Head Shells -->
    <!-- TODO: Update inertia and collision -->
    <link name="head_shell_link">
      <visual>
        <origin
          xyz="0 0.41 0"
          rpy="${M_PI/2} ${M_PI/2} 0"/>
        <geometry>
          <mesh
            filename="package://vizzy_description/meshes/head/head.dae"/>
        </geometry>
        <material name="light_gray_1"/>
      </visual>
      <inertial>
        <origin rpy="0 0 0" xyz="0.0 0.0 0.0"/>
        <mass value="0.001"/>
        <inertia ixx="0.01" ixy="0" ixz="0" iyy="0.01" iyz="0" izz="0.01"/>
      </inertial>
      <collision>
        <origin rpy="0 0 0" xyz="0.0 0.0 0.0"/>
        <geometry>
          <cylinder length="0.001" radius="0.005"/>
        </geometry>
      </collision>
    </link>

    <joint name="head_shell_joint"
      type="fixed">
      <origin
        xyz="0 0 0"
        rpy="0 0 0"/>
      <parent
        link="neck_tilt_link"/>
      <child
        link="head_shell_link"/>
    </joint>

    <link name="face_shell_link">
      <visual>
        <origin
          xyz="-0.394 0.69 0.0995"
          rpy="0 ${M_PI/2} 0"/>
        <geometry>
          <mesh
            filename="package://vizzy_description/meshes/head/face.dae"/>
        </geometry>
        <material name="light_gray_1"/>
      </visual>
      <inertial>
        <origin rpy="0 0 0" xyz="0.0 0.0 0.0"/>
        <mass value="0.001"/>
        <inertia ixx="0.01" ixy="0" ixz="0" iyy="0.01" iyz="0" izz="0.01"/>
      </inertial>
      <collision>
        <origin rpy="0 0 0" xyz="0.0 0.0 0.0"/>
        <geometry>
          <cylinder length="0.001" radius="0.005"/>
        </geometry>
      </collision>
    </link>

    <joint name="face_shell_joint"
      type="fixed">
      <origin
        xyz="0 0 0"
        rpy="0 0 0"/>
      <parent
        link="neck_tilt_link"/>
      <child
        link="face_shell_link"/>
    </joint>

    <!-- Eyes tilt -->
    <link name="eyes_tilt_link">
      <xacro:vizzy_eyes_tilt_link_inertial/>
      <visual>
        <origin
          xyz="-0.007 -0.002 -0.002"
          rpy="0 0 -1.2012"/>
        <geometry>
          <mesh
            filename="package://vizzy_description/meshes/head/eyes_tilt.dae"/>
        </geometry>
        <material name="light_gray_3"/>
      </visual>
      <xacro:vizzy_eyes_tilt_link_collision/>
    </link>

    <joint name="eyes_tilt_joint"
      type="revolute">
      <origin
        xyz="-0.12379 -0.04755 0"
        rpy="${M_PI} 0 -2.77199351787335"/>
      <parent
        link="neck_tilt_link"/>
      <child
        link="eyes_tilt_link"/>
      <axis
        xyz="0 0 1" />
      <limit lower="-0.663225116" upper="0.663225116" effort="10.0" velocity="5.0" />
      <dynamics damping="0.0" friction="5.0"/>
    </joint>

    <!-- Eyes center virtual link and joint -->
    <link name="eyes_center_link">
      <inertial>
        <origin
          xyz="0 0 0"
          rpy="0 0 0"/>
        <mass
          value="0.1"/>
        <inertia
          ixx="0.001" ixy="0.0" ixz="0.0"
          iyy="0.001" iyz="0.0" izz="0.001"/>
      </inertial>
    </link>

    <joint name="eyes_center_joint"
      type="fixed">
      <origin
        xyz="0 0 0"
        rpy="${M_PI/2} 0 0.369599135716446" />
      <parent
        link="eyes_tilt_link" />
      <child
        link="eyes_center_link" />
      <axis
        xyz="0 0 1" />
      <limit lower="-0.698131" upper="0.698131" effort="10.0" velocity="5.0" />
    </joint>

    <!-- Eyes visual center virtual link and joint -->
    <link name="eyes_center_vision_link">
      <inertial>
        <origin
          xyz="0 0 0"
          rpy="0 0 0"/>
        <mass
          value="0.1"/>
        <inertia
          ixx="0.001" ixy="0.0" ixz="0.0"
          iyy="0.001" iyz="0.0" izz="0.001"/>
      </inertial>
    </link>

    <joint name="eyes_center_vision_joint"
      type="fixed">
      <origin
        xyz="0 0 0"
        rpy="${-M_PI/2} 0 ${-M_PI/2}"/>
      <parent
        link="eyes_center_link"/>
      <child
        link="eyes_center_vision_link"/>
    </joint>

    <!-- Eyes -->

    <!-- Left eye -->
    <link name="l_eye_link">
      <xacro:vizzy_eye_link_inertial/>
      <visual>
        <origin
          xyz="0 0 0"
          rpy="0 0 ${M_PI/2}" />
        <geometry>
          <mesh
            filename="package://vizzy_description/meshes/head/eye.dae" />
        </geometry>
        <material name="gray_1"/>
      </visual>
      <xacro:vizzy_eye_link_collision/>
    </link>

    <joint name="l_eye_joint"
      type="revolute">
      <origin
        xyz="0 0.102 0"
        rpy="0 ${M_PI} 0" />
      <parent
        link="eyes_center_link" />
      <child
        link="l_eye_link" />
      <axis
        xyz="0 0 1" />
      <limit lower="-1.0" upper="1.0" effort="1000.0" velocity="5.0" />
      <dynamics damping="0.0" friction="5.0"/>
    </joint>

    <!-- Right eye -->
    <link name="r_eye_link">
      <xacro:vizzy_eye_link_inertial/>
      <visual>
        <origin
          xyz="0 0 0"
          rpy="0 0 ${M_PI/2}" />
        <geometry>
          <mesh
            filename="package://vizzy_description/meshes/head/eye.dae" />
        </geometry>
        <material name="gray_1"/>
      </visual>
      <xacro:vizzy_eye_link_collision/>
    </link>

    <joint name="r_eye_joint"
      type="revolute">
      <origin
        xyz="0 -0.102 0"
        rpy="0 ${M_PI} 0" />
      <parent
        link="eyes_center_link" />
      <child
        link="r_eye_link" />
      <axis
        xyz="0 0 1" />
      <limit lower="-1.0" upper="1.0" effort="1000.0" velocity="5.0"/>
      <dynamics damping="0.0" friction="5.0"/>
    </joint>

    <!-- Cameras -->

    <!-- Right camera -->
    <link name="r_camera_link">
     <visual>
        <origin xyz="0 0 0" rpy="0 0 0"/>
        <geometry>
          <box size="0.001 0.001 0.001"/>
        </geometry>
      </visual>
    </link>

    <joint name="r_camera_joint" type="fixed">
      <origin xyz="-0.0275 0 0" rpy="0 ${M_PI} 0"/>
      <parent link="r_eye_link"/>
      <child link="r_camera_link" />
    </joint>

    <link name="r_camera_vision_link">
     <visual>
        <origin xyz="0 0 0" rpy="0 0 0" />
        <geometry>
          <box size="0.001 0.001 0.001" />
        </geometry>
      </visual>
    </link>

    <joint name="r_camera_vision_joint" type="fixed">
      <origin xyz="0 0 0" rpy="${M_PI/2} 0 ${-M_PI/2}" />
      <parent link="r_eye_link"/>
      <child link="r_camera_vision_link" />
    </joint>

    <!-- Left camera -->
    <link name="l_camera_link">
     <visual>
        <origin xyz="0 0 0" rpy="0 0 0" />
        <geometry>
          <box size="0.001 0.001 0.001" />
        </geometry>
      </visual>
    </link>

    <joint name="l_camera_joint" type="fixed">
      <origin xyz="-0.0275 0 0" rpy="0 ${M_PI} 0"/>
      <parent link="l_eye_link"/>
      <child link="l_camera_link"/>
    </joint>

    <link name="l_camera_vision_link">
     <visual>
        <origin xyz="0 0 0" rpy="0 0 0"/>
        <geometry>
          <box size="0.001 0.001 0.001"/>
        </geometry>
      </visual>
    </link>

    <joint name="l_camera_vision_joint" type="fixed">
      <origin xyz="0 0 0" rpy="${M_PI/2} 0 ${-M_PI/2}"/>
      <parent link="l_eye_link"/>
      <child link="l_camera_vision_link"/>
    </joint>

    <!-- Ego frame -->
    <link name="ego_frame">
      <inertial>
        <origin xyz="0 0 0" rpy="0 0 0"/>
        <mass value="0.001"/> 
        <inertia  
          ixx="0.001" ixy="0.0" ixz="0.0" 
          iyy="0.001" iyz="0.0" izz="0.001"/>         
      </inertial>
    </link>

    <joint name="ego_joint" type="fixed">
      <origin
        xyz="0 0.370 0"
        rpy="0 ${M_PI/2} ${M_PI}"/>
      <parent link="waist_link"/>
      <child link="ego_frame"/>
    </joint>

    <!-- Head origin -->
    <link name="head_origin_frame">
      <inertial>
        <origin xyz="0 0 0" rpy="0 0 0"/>
        <mass value="0.001"/> 
        <inertia  
          ixx="0.001" ixy="0.0" ixz="0.0" 
          iyy="0.001" iyz="0.0" izz="0.001"/>         
      </inertial>
    </link>

    <joint name="head_origin_joint" type="fixed">
      <origin
        xyz="0 -0.04755 0"
        rpy="0 -${M_PI/2} 0"/>
      <parent link="neck_tilt_link"/>
      <child link="head_origin_frame"/>
    </joint>

    <!-- Gazebo extensions -->
    <xacro:head_transmissions />

  </xacro:macro>
</robot>
