<robot
  name="vizzy-description" >
  
  <link name="base_footprint">
   <!--<visual>
     <origin xyz="0 0 0" rpy="0 0 0" />
     <geometry>
       <box size="0.001 0.001 0.001" />
     </geometry>
   </visual>-->
  </link>

  <joint name="base_footprint_joint" type="fixed">
   <origin xyz="0 0 0" rpy="0 0 0" />
   <parent link="base_footprint"/>
   <child link="base_link" />
  </joint>
  
  <link
    name="base_link">
    <inertial>
      <origin
        xyz="0.19 0 0.2"
        rpy="0 0 0" />
      <mass
        value="11.7973473742999" />
      <inertia
        ixx="0.438925207385402"
        ixy="0.000141568676799447"
        ixz="7.95805262167885E-07"
        iyy="0.326554522375815"
        iyz="0.00194386671838748"
        izz="0.296176192213331" />
    </inertial>
    <visual>
      <origin
        xyz="0.188 0.001 0.197"
        rpy="0 0 0" />
      <geometry>
        <mesh
          filename="package://vizzy-description/meshes/Segway.dae" />
      </geometry>
      <material
        name="">
        <color
          rgba="0.866666666666667 0.866666666666667 0.890196078431373 1" />
      </material>
    </visual>
    <collision>
      <origin
        xyz="0.19 0 0.2"
        rpy="0 0 0" />
      <geometry>
        <mesh
          filename="package://vizzy-description/meshes/Segway.dae" />
      </geometry>
    </collision>
  </link>
  <link
    name="f_wheel_base_link">
    <inertial>
      <origin
        xyz="-0.0118 0.0084 0.083"
        rpy="0 0 0" />
      <mass
        value="0.0522202580480446" />
      <inertia
        ixx="0.000109063640814005"
        ixy="1.29634203029402E-06"
        ixz="-2.56834920297101E-05"
        iyy="0.000107815897797672"
        iyz="1.74895161672912E-05"
        izz="3.21409232257602E-05" />
    </inertial>
    <visual>
      <origin
        xyz="-0.0118 0.0084 0.083"
        rpy="0 0 0" />
      <geometry>
        <mesh
          filename="package://vizzy-description/meshes/Front.dae" />
      </geometry>
      <material
        name="">
        <color
          rgba="0.796078431372549 0.823529411764706 0.937254901960784 1" />
      </material>
    </visual>
    <collision>
      <origin
        xyz="-0.0118 0.0084 0.083"
        rpy="0 0 0" />
      <geometry>
        <mesh
          filename="package://vizzy-description/meshes/Front.dae" />
      </geometry>
    </collision>
  </link>
  <joint
    name="f_wheel_base_joint"
    type="continuous">
    <origin
      xyz="0.43986 0.001 0.14806"
      rpy="3.1416 0.0 0.0" />
    <parent
      link="base_link" />
    <child
      link="f_wheel_base_link" />
    <axis
      xyz="0 0 1" />
    <dynamics damping="0.1"/>
  </joint>
  <link
    name="f_wheel_link">
    <inertial>
      <origin
        xyz="0 0 0"
        rpy="0 0 0" />
      <mass
        value="0.146715525294139" />
      <inertia
        ixx="0.000105012932391273"
        ixy="-1.06408513998821E-20"
        ixz="-6.7762635780344E-21"
        iyy="0.000105012932391273"
        iyz="4.99749438880037E-20"
        izz="0.00019960379578771" />
    </inertial>
    <visual>
      <origin
        xyz="0 0 0"
        rpy="0 0 0" />
      <geometry>
        <mesh
          filename="package://vizzy-description/meshes/F_W.dae" />
      </geometry>
      <material
        name="">
        <color
          rgba="0.796078431372549 0.823529411764706 0.937254901960784 1" />
      </material>
    </visual>
    <collision>
      <origin
        xyz="0 0 0"
        rpy="0 0 0" />
      <geometry>
        <mesh
          filename="package://vizzy-description/meshes/F_W.dae" />
      </geometry>
    </collision>
  </link>
  <joint
    name="f_wheel_joint"
    type="continuous">
    <origin
      xyz="-0.030027 0.020142 0.138923486"
      rpy="-1.5708 0.83904 2.5507" />
    <parent
      link="f_wheel_base_link" />
    <child
      link="f_wheel_link" />
    <axis
      xyz="0 0 1" />
  </joint>
  <link
    name="b_wheel_base_link">
    <inertial>
      <origin
        xyz="-0.0118 0.0084 0.083"
        rpy="0 0 0" />
      <mass
        value="0.0522202580480446" />
      <inertia
        ixx="0.000109063640814005"
        ixy="1.29634203029405E-06"
        ixz="-2.568349202971E-05"
        iyy="0.000107815897797672"
        iyz="1.74895161672911E-05"
        izz="3.21409232257601E-05" />
    </inertial>
    <visual>
      <origin
        xyz="-0.0118 0.0084 0.083"
        rpy="0 0 0" />
      <geometry>
        <mesh
          filename="package://vizzy-description/meshes/Back.dae" />
      </geometry>
      <material
        name="">
        <color
          rgba="0.796078431372549 0.823529411764706 0.937254901960784 1" />
      </material>
    </visual>
    <collision>
      <origin
        xyz="-0.0118 0.0084 0.083"
        rpy="0 0 0" />
      <geometry>
        <mesh
          filename="package://vizzy-description/meshes/Back.dae" />
      </geometry>
    </collision>
  </link>
  <joint
    name="b_wheel_base_joint"
    type="continuous">
    <origin
      xyz="-0.060139 0.001 0.14806"
      rpy="3.1416 0.0 0.0" />
    <parent
      link="base_link" />
    <child
      link="b_wheel_base_link" />
    <axis
      xyz="0 0 1" />
    <dynamics damping="0.1"/>
  </joint>
  <link
    name="b_wheel_link">
    <inertial>
      <origin
        xyz="0 0 0"
        rpy="0 0 0" />
      <mass
        value="0.146715525294139" />
      <inertia
        ixx="0.000105012932391273"
        ixy="1.07996700774923E-20"
        ixz="-1.6940658945086E-21"
        iyy="0.000105012932391273"
        iyz="-1.18584612615602E-20"
        izz="0.00019960379578771" />
    </inertial>
    <visual>
      <origin
        xyz="0 0 0"
        rpy="0 0 0" />
      <geometry>
        <mesh
          filename="package://vizzy-description/meshes/B_W.dae" />
      </geometry>
      <material
        name="">
        <color
          rgba="0.796078431372549 0.823529411764706 0.937254901960784 1" />
      </material>
    </visual>
    <collision>
      <origin
        xyz="0 0 0"
        rpy="0 0 0" />
      <geometry>
        <mesh
          filename="package://vizzy-description/meshes/B_W.dae" />
      </geometry>
    </collision>
  </link>
  <joint
    name="b_wheel_joint"
    type="continuous">
    <origin
      xyz="-0.0300271872634975 0.0201420335543447 0.138923486"
      rpy="-1.5707963267949 0.83904346430428 2.5507386456365" />
    <parent
      link="b_wheel_base_link" />
    <child
      link="b_wheel_link" />
    <axis
      xyz="0 0 1" />
  </joint>
  <link
    name="r_wheel_link">
    <inertial>
      <origin
        xyz="0 0 0"
        rpy="0 0 0" />
      <mass
        value="1.22861917507719" />
      <inertia
        ixx="0.0106873251772162"
        ixy="4.79944507056635E-17"
        ixz="3.53158602954754E-16"
        iyy="0.0106873821917694"
        iyz="1.38940097207607E-06"
        izz="0.0205152843016012" />
    </inertial>
    <visual>
      <origin
        xyz="0 0 0"
        rpy="0 0 0" />
      <geometry>
        <mesh
          filename="package://vizzy-description/meshes/Left.dae" />
      </geometry>
      <material
        name="">
        <color
          rgba="0.494117647058824 0.494117647058824 0.494117647058824 1" />
      </material>
    </visual>
    <collision>
      <origin
        xyz="0 0 0"
        rpy="0 0 0" />
      <geometry>
        <mesh
          filename="package://vizzy-description/meshes/Left.dae" />
      </geometry>
    </collision>
  </link>
  <joint
    name="r_wheel_joint"
    type="continuous">
    <origin
      xyz="0.18986 0.246 0.15814"
      rpy="1.5708 1.5708 0" />
    <parent
      link="base_link" />
    <child
      link="r_wheel_link" />
    <axis
      xyz="0 0 1" />
  </joint>
  <link
    name="l_wheel_link">
    <inertial>
      <origin
        xyz="0 0 0"
        rpy="3.15 0 0" />
      <mass
        value="1.22861917507742" />
      <inertia
        ixx="0.0106873471854323"
        ixy="7.49808591987845E-18"
        ixz="-1.93571153328442E-16"
        iyy="0.0106874041999854"
        iyz="1.38940098137139E-06"
        izz="0.0205152843016018" />
    </inertial>
    <visual>
      <origin
        xyz="0 0 0"
        rpy="3.15 0 0" />
      <geometry>
        <mesh
          filename="package://vizzy-description/meshes/Right.dae" />
      </geometry>
      <material
        name="">
        <color
          rgba="0.494117647058824 0.494117647058824 0.494117647058824 1" />
      </material>
    </visual>
    <collision>
      <origin
        xyz="0 0 0"
        rpy="3.15 0 0" />
      <geometry>
        <mesh
          filename="package://vizzy-description/meshes/Right.dae" />
      </geometry>
    </collision>
  </link>
  <joint
    name="l_wheel_joint"
    type="continuous">
    <origin
      xyz="0.18986 -0.244 0.15814"
      rpy="1.5708 1.5708 0" />
    <parent
      link="base_link" />
    <child
      link="l_wheel_link" />
    <axis
      xyz="0 0 1" />
  </joint>

  <link
    name="waist_link">
    <inertial>
      <origin
        xyz="0.0 0.113 0.0"
        rpy="0.0 3.14159265358979 0.0" />
      <mass
        value="1.52801214308198" />
      <inertia
        ixx="0.0152197122703999"
        ixy="-0.000217387828540953"
        ixz="-2.16469131237159E-06"
        iyy="0.00325229915840824"
        iyz="0.000261589513226157"
        izz="0.0128988018329273" />
    </inertial>
    <visual>
      <origin
        xyz="0.0 0.113 0.0"
        rpy="0.0 3.14159265358979 0.0" />
      <geometry>
        <mesh
          filename="package://vizzy-description/meshes/M0.dae" />
      </geometry>
      <material
        name="">
        <color
          rgba="0.898039215686275 0.917647058823529 0.929411764705882 1" />
      </material>
    </visual>
    <collision>
      <origin
        xyz="0.0 0.113 0.0"
        rpy="0.0 3.14159265358979 0.0" />
      <geometry>
        <mesh
          filename="package://vizzy-description/meshes/M0.dae" />
      </geometry>
    </collision>
  </link>
  <joint
    name="waist_joint"
    type="revolute">
    <origin
      xyz="0.189861451370331 0.0 0.535796910356883"
      rpy="1.5708 0.0 0.0" />
    <parent
      link="base_link" />
    <child
      link="waist_link" />
    <axis
      xyz="0 0 1" />
    <limit lower="-0.34906585" upper="0.34906585" effort="10" velocity="3" />
    <dynamics damping="0.1"/>
  </joint>
  
  <link name="r_shoulder_scapula_link">
    <inertial>
      <origin
        xyz="0 0 0.166"
        rpy="0 -3.1416 0" />
      <mass
        value="0.328838093982794" />
      <inertia
        ixx="0.00123108428695986"
        ixy="-7.89100940163704E-11"
        ixz="6.34844936183615E-10"
        iyy="0.000919898935949979"
        iyz="7.50425183699034E-05"
        izz="0.000480033534097503" />
    </inertial>
    <visual>
      <origin
        xyz="0 0 0.166"
        rpy="0 -3.1416 0" />
      <geometry>
        <mesh
          filename="package://vizzy-description/meshes/M0R.dae" />
      </geometry>
      <material
        name="">
        <color
          rgba="0.898039215686275 0.917647058823529 0.929411764705882 1" />
      </material>
    </visual>
    <collision>
      <origin
        xyz="0 0 0.166"
        rpy="0 -3.1416 0" />
      <geometry>
        <mesh
          filename="package://vizzy-description/meshes/M0R.dae" />
      </geometry>
    </collision>
  </link>
  <joint
    name="r_shoulder_scapula_joint"
    type="revolute">
    <origin
      xyz="0.0 0.0 -0.0805"
      rpy="-1.5707 0.0 0.0" />
    <parent
      link="waist_link" />
    <child
      link="r_shoulder_scapula_link" />
    <axis
      xyz="0 0 1" />
    <limit lower="-0.314159265" upper="0.314159265" effort="10" velocity="3" />
  </joint>
  <link
    name="r_shoulder_flection_link">
    <inertial>
      <origin
        xyz="0.0 0.0 0.0479999999999997"
        rpy="0.0 3.1416 -4.1963" />
      <mass
        value="0.32970750458976" />
      <inertia
        ixx="0.00116793345082586"
        ixy="-0.000134890089770505"
        ixz="3.78931445548874E-05"
        iyy="0.00101232051019094"
        iyz="-6.56607928268466E-05"
        izz="0.000480378760663095" />
    </inertial>
    <visual>
      <origin
        xyz="0.0 0.0 0.0479999999999997"
        rpy="0.0 3.1416 -4.1963" />
      <geometry>
        <mesh
          filename="package://vizzy-description/meshes/M1R.dae" />
      </geometry>
      <material
        name="">
        <color
          rgba="0.898039215686275 0.917647058823529 0.929411764705882 1" />
      </material>
    </visual>
    <collision>
      <origin
        xyz="0.0 0.0 0.0479999999999997"
        rpy="0.0 3.1416 -4.1963" />
      <geometry>
        <mesh
          filename="package://vizzy-description/meshes/M1R.dae" />
      </geometry>
    </collision>
  </link>
  <joint
    name="r_shoulder_flection_joint"
    type="revolute">
    <origin
      xyz="0.0 0.0 0.212"
      rpy="-1.5707 0.0 0.0" />
    <parent
      link="r_shoulder_scapula_link" />
    <child
      link="r_shoulder_flection_link" />
    <axis
      xyz="0 0 1" />
    <limit lower="-1.30899694" upper="2.35619449" effort="10" velocity="3" />
  </joint>
  <link
    name="r_shoulder_abduction_link">
    <inertial>
      <origin
        xyz="0.034 0.009 -0.001"
        rpy="0 3.1416 -1.2217" />
      <mass
        value="0.337952134649786" />
      <inertia
        ixx="0.000722844158320218"
        ixy="-4.62401500200836E-05"
        ixz="-1.45396813798355E-06"
        iyy="0.000316566986726189"
        iyz="1.40155770580819E-05"
        izz="0.00057775987279214" />
    </inertial>
    <visual>
      <origin
        xyz="0.034 0.009 -0.001"
        rpy="0 3.1416 -1.2217" />
      <geometry>
        <mesh
          filename="package://vizzy-description/meshes/M2R.dae" />
      </geometry>
      <material
        name="">
        <color
          rgba="0.898039215686275 0.917647058823529 0.929411764705882 1" />
      </material>
    </visual>
    <collision>
      <origin
        xyz="0.034 0.009 -0.001"
        rpy="0 3.1416 -1.2217" />
      <geometry>
        <mesh
          filename="package://vizzy-description/meshes/M2R.dae" />
      </geometry>
    </collision>
  </link>
  <joint
    name="r_shoulder_abduction_joint"
    type="revolute">
    <origin
      xyz="0.0 0.0 0.10256"
      rpy="1.5707 0.0 1.5707" />
    <parent
      link="r_shoulder_flection_link" />
    <child
      link="r_shoulder_abduction_link" />
    <axis
      xyz="0 0 1" />
    <limit lower="0" upper="1.30899694" effort="10" velocity="3" />
  </joint>
  <link
    name="r_shoulder_rotation_link">
    <inertial>
      <origin
        xyz="-0.003 -0.006 0.127"
        rpy="3.1416 0 -1.5707" />
      <mass
        value="0.302328098083101" />
      <inertia
        ixx="0.000615246412768918"
        ixy="-4.12473635541355E-06"
        ixz="-6.13280078197927E-05"
        iyy="0.000574849538917934"
        iyz="-2.49114717380023E-05"
        izz="0.000240227819685505" />
    </inertial>
    <visual>
      <origin
        xyz="-0.003 -0.006 0.127"
        rpy="3.1416 0 -1.5707" />
      <geometry>
        <mesh
          filename="package://vizzy-description/meshes/M3R.dae" />
      </geometry>
      <material
        name="">
        <color
          rgba="0.898039215686275 0.917647058823529 0.929411764705882 1" />
      </material>
    </visual>
    <collision>
      <origin
        xyz="-0.003 -0.006 0.127"
        rpy="3.1416 0 -1.5707" />
      <geometry>
        <mesh
          filename="package://vizzy-description/meshes/M3R.dae" />
      </geometry>
    </collision>
  </link>
  <joint
    name="r_shoulder_rotation_joint"
    type="revolute">
    <origin
      xyz="0.0 0.0 0.0"
      rpy="-1.5707 0.0 -1.2217" />
    <parent
      link="r_shoulder_abduction_link" />
    <child
      link="r_shoulder_rotation_link" />
    <axis
      xyz="0 0 1" />
    <limit lower="-1.48352986" upper="1.48352986" effort="10" velocity="3" />
  </joint>
  <link
    name="r_elbow_flection_link">
    <inertial>
      <origin
        xyz="-0.002 -0.035 0.0"
        rpy="0 0 3.1416" />
      <mass
        value="0.224019872068973" />
      <inertia
        ixx="0.000224266812490421"
        ixy="7.91977782063514E-06"
        ixz="2.45606472556753E-07"
        iyy="9.89758932648508E-05"
        iyz="9.59616898464483E-06"
        izz="0.000213841891572994" />
    </inertial>
    <visual>
      <origin
        xyz="-0.002 -0.035 0.0"
        rpy="0 0 3.1416" />
      <geometry>
        <mesh
          filename="package://vizzy-description/meshes/M4R.dae" />
      </geometry>
      <material
        name="">
        <color
          rgba="0.898039215686275 0.917647058823529 0.929411764705882 1" />
      </material>
    </visual>
    <collision>
      <origin
        xyz="-0.002 -0.035 0.0"
        rpy="0 0 3.1416" />
      <geometry>
        <mesh
          filename="package://vizzy-description/meshes/M4R.dae" />
      </geometry>
    </collision>
  </link>
  <joint
    name="r_elbow_flection_joint"
    type="revolute">
    <origin
      xyz="0.0 0.0 0.16296"
      rpy="-1.5707 0.0 1.5707" />
    <parent
      link="r_shoulder_rotation_link" />
    <child
      link="r_elbow_flection_link" />
    <axis
      xyz="0 0 1" />
    <limit lower="0" upper="1.91986218" effort="10" velocity="3" />
  </joint>
  <link
    name="r_forearm_pronation_link">
    <inertial>
      <origin
        xyz="0.00 -0.007 -0.11"
        rpy="0.0 0.0 1.5707" />
      <mass
        value="0.19252548105039" />
      <inertia
        ixx="0.000215803119910502"
        ixy="-6.086463167521E-08"
        ixz="9.78455040630467E-06"
        iyy="0.000229047404557263"
        iyz="-3.19642916101682E-07"
        izz="0.000102658318305363" />
    </inertial>
    <visual>
      <origin
        xyz="0.00 -0.007 -0.11"
        rpy="0.0 0.0 1.5707" />
      <geometry>
        <mesh
          filename="package://vizzy-description/meshes/M5R.dae" />
      </geometry>
      <material
        name="">
        <color
          rgba="0.898039215686275 0.917647058823529 0.929411764705882 1" />
      </material>
    </visual>
    <collision>
      <origin
        xyz="0.00 -0.007 -0.11"
        rpy="0.0 0.0 1.5707" />
      <geometry>
        <mesh
          filename="package://vizzy-description/meshes/M5R.dae" />
      </geometry>
    </collision>
  </link>
  <joint
    name="r_forearm_pronation_joint"
    type="revolute">
    <origin
      xyz="0.0 0.0 0.0"
      rpy="1.5707 0.0 3.1416" />
    <parent
      link="r_elbow_flection_link" />
    <child
      link="r_forearm_pronation_link" />
    <axis
      xyz="0 0 1" />
    <limit lower="-1.48352986" upper="1.48352986" effort="10" velocity="3" />
  </joint>
  <link
    name="r_wrist_abduction_link">
    <inertial>
      <origin
        xyz="0.0047 0.028 -0.003"
        rpy="3.1416 3.1416 0" />
      <mass
        value="0.15130263687109" />
      <inertia
        ixx="0.000206280948481805"
        ixy="-2.10167871847464E-05"
        ixz="-1.95502541303483E-06"
        iyy="7.18084114032176E-05"
        iyz="1.63557763545568E-05"
        izz="0.000199867817507994" />
    </inertial>
    <visual>
      <origin
        xyz="0.0047 0.028 -0.003"
        rpy="3.1416 3.1416 0" />
      <geometry>
        <mesh
          filename="package://vizzy-description/meshes/M6R.dae" />
      </geometry>
      <material
        name="">
        <color
          rgba="0.898039215686275 0.917647058823529 0.929411764705882 1" />
      </material>
    </visual>
    <collision>
      <origin
        xyz="0.0047 0.028 -0.003"
        rpy="3.1416 3.1416 0" />
      <geometry>
        <mesh
          filename="package://vizzy-description/meshes/M6R.dae" />
      </geometry>
    </collision>
  </link>
  <joint
    name="r_wrist_abduction_joint"
    type="revolute">
    <origin
      xyz="0.0 0.0 -0.18925"
      rpy="1.5707 0.0 0.0" />
    <parent
      link="r_forearm_pronation_link" />
    <child
      link="r_wrist_abduction_link" />
    <axis
      xyz="0 0 1" />
    <limit lower="-0.610865238" upper="0.610865238" effort="10" velocity="3" />
  </joint>
  <link
    name="r_wrist_flection_link">
    <inertial>
      <origin
        xyz="0 0 -0.0068"
        rpy="0 3.1416 -1.5708" />
      <mass
        value="0.263247942991542" />
      <inertia
        ixx="0.00142191847625323"
        ixy="7.01996302951171E-06"
        ixz="-4.24188980462336E-05"
        iyy="0.000427941498537125"
        iyz="0.000132013848915951"
        izz="0.00103049250587026" />
    </inertial>
    <visual>
      <origin
        xyz="-0.106 -0.0077 0.017"
        rpy="0.0 3.1416 1.5707" />
      <geometry>
        <mesh
          filename="package://vizzy-description/meshes/M7R.dae" />
      </geometry>
      <material
        name="">
        <color
          rgba="0.898039215686275 0.917647058823529 0.929411764705882 1" />
      </material>
    </visual>
    <collision>
      <origin
        xyz="0 0 -0.0068"
        rpy="0 3.1416 -1.5708" />
      <geometry>
        <mesh
          filename="package://vizzy-description/meshes/M7R.dae" />
      </geometry>
    </collision>
  </link>
  <joint
    name="r_wrist_flection_joint"
    type="revolute">
    <origin
      xyz="0.0 0.0 0.0"
      rpy="-1.5707 0.0 1.5707" />
    <parent
      link="r_wrist_abduction_link" />
    <child
      link="r_wrist_flection_link" />
    <axis
      xyz="0 0 1" />
    <limit lower="-0.610865238" upper="0.610865238" effort="10" velocity="3" />
  </joint>
  <link name="r_palm_link">
   <visual>
      <origin xyz="0 0 0" rpy="0 0 0" />
      <geometry>
        <box size="0.001 0.001 0.001" />
      </geometry>
    </visual>
  </link>
  <joint name="r_palm_joint" type="fixed">
    <origin xyz="-0.1 0 0.0" rpy="1.5707 0.0 0.0" />
    <parent link="r_wrist_flection_link"/>
    <child link="r_palm_link" />
  </joint>

</robot>
